{
    DataVersion: 3465,
    size: [5, 7, 6],
    data: [
        {pos: [0, 0, 0], state: "minecraft:netherrack"},
        {pos: [0, 0, 1], state: "minecraft:netherrack"},
        {pos: [0, 0, 2], state: "minecraft:netherrack"},
        {pos: [0, 0, 3], state: "minecraft:netherrack"},
        {pos: [0, 0, 4], state: "minecraft:netherrack"},
        {pos: [0, 0, 5], state: "minecraft:netherrack"},
        {pos: [1, 0, 0], state: "minecraft:netherrack"},
        {pos: [1, 0, 1], state: "minecraft:netherrack"},
        {pos: [1, 0, 2], state: "minecraft:netherrack"},
        {pos: [1, 0, 3], state: "minecraft:netherrack"},
        {pos: [1, 0, 4], state: "minecraft:netherrack"},
        {pos: [1, 0, 5], state: "minecraft:netherrack"},
        {pos: [2, 0, 0], state: "minecraft:netherrack"},
        {pos: [2, 0, 1], state: "minecraft:netherrack"},
        {pos: [2, 0, 2], state: "minecraft:bedrock"},
        {pos: [2, 0, 3], state: "minecraft:bedrock"},
        {pos: [2, 0, 4], state: "minecraft:netherrack"},
        {pos: [2, 0, 5], state: "minecraft:netherrack"},
        {pos: [3, 0, 0], state: "minecraft:netherrack"},
        {pos: [3, 0, 1], state: "minecraft:netherrack"},
        {pos: [3, 0, 2], state: "minecraft:netherrack"},
        {pos: [3, 0, 3], state: "minecraft:netherrack"},
        {pos: [3, 0, 4], state: "minecraft:netherrack"},
        {pos: [3, 0, 5], state: "minecraft:netherrack"},
        {pos: [4, 0, 0], state: "minecraft:netherrack"},
        {pos: [4, 0, 1], state: "minecraft:netherrack"},
        {pos: [4, 0, 2], state: "minecraft:netherrack"},
        {pos: [4, 0, 3], state: "minecraft:netherrack"},
        {pos: [4, 0, 4], state: "minecraft:netherrack"},
        {pos: [4, 0, 5], state: "minecraft:netherrack"},
        {pos: [0, 1, 0], state: "minecraft:netherrack"},
        {pos: [0, 1, 1], state: "minecraft:netherrack"},
        {pos: [0, 1, 2], state: "minecraft:netherrack"},
        {pos: [0, 1, 3], state: "minecraft:netherrack"},
        {pos: [0, 1, 4], state: "minecraft:netherrack"},
        {pos: [0, 1, 5], state: "minecraft:netherrack"},
        {pos: [1, 1, 0], state: "minecraft:netherrack"},
        {pos: [1, 1, 1], state: "minecraft:netherrack"},
        {pos: [1, 1, 2], state: "minecraft:netherrack"},
        {pos: [1, 1, 3], state: "minecraft:netherrack"},
        {pos: [1, 1, 4], state: "minecraft:netherrack"},
        {pos: [1, 1, 5], state: "minecraft:netherrack"},
        {pos: [2, 1, 0], state: "minecraft:netherrack"},
        {pos: [2, 1, 1], state: "minecraft:netherrack"},
        {pos: [2, 1, 2], state: "minecraft:netherrack"},
        {pos: [2, 1, 3], state: "minecraft:netherrack"},
        {pos: [2, 1, 4], state: "minecraft:netherrack"},
        {pos: [2, 1, 5], state: "minecraft:netherrack"},
        {pos: [3, 1, 0], state: "minecraft:netherrack"},
        {pos: [3, 1, 1], state: "minecraft:netherrack"},
        {pos: [3, 1, 2], state: "minecraft:netherrack"},
        {pos: [3, 1, 3], state: "minecraft:netherrack"},
        {pos: [3, 1, 4], state: "minecraft:netherrack"},
        {pos: [3, 1, 5], state: "minecraft:netherrack"},
        {pos: [4, 1, 0], state: "minecraft:netherrack"},
        {pos: [4, 1, 1], state: "minecraft:netherrack"},
        {pos: [4, 1, 2], state: "minecraft:netherrack"},
        {pos: [4, 1, 3], state: "minecraft:netherrack"},
        {pos: [4, 1, 4], state: "minecraft:netherrack"},
        {pos: [4, 1, 5], state: "minecraft:netherrack"},
        {pos: [0, 2, 0], state: "minecraft:netherrack"},
        {pos: [0, 2, 1], state: "minecraft:netherrack"},
        {pos: [0, 2, 2], state: "minecraft:netherrack"},
        {pos: [0, 2, 3], state: "minecraft:netherrack"},
        {pos: [0, 2, 4], state: "minecraft:netherrack"},
        {pos: [0, 2, 5], state: "minecraft:netherrack"},
        {pos: [1, 2, 0], state: "minecraft:netherrack"},
        {pos: [1, 2, 1], state: "minecraft:netherrack"},
        {pos: [1, 2, 2], state: "minecraft:obsidian"},
        {pos: [1, 2, 3], state: "minecraft:obsidian"},
        {pos: [1, 2, 4], state: "minecraft:netherrack"},
        {pos: [1, 2, 5], state: "minecraft:netherrack"},
        {pos: [2, 2, 0], state: "minecraft:netherrack"},
        {pos: [2, 2, 1], state: "minecraft:obsidian"},
        {pos: [2, 2, 2], state: "minecraft:obsidian"},
        {pos: [2, 2, 3], state: "minecraft:obsidian"},
        {pos: [2, 2, 4], state: "minecraft:obsidian"},
        {pos: [2, 2, 5], state: "minecraft:netherrack"},
        {pos: [3, 2, 0], state: "minecraft:netherrack"},
        {pos: [3, 2, 1], state: "minecraft:netherrack"},
        {pos: [3, 2, 2], state: "minecraft:obsidian"},
        {pos: [3, 2, 3], state: "minecraft:obsidian"},
        {pos: [3, 2, 4], state: "minecraft:netherrack"},
        {pos: [3, 2, 5], state: "minecraft:netherrack"},
        {pos: [4, 2, 0], state: "minecraft:netherrack"},
        {pos: [4, 2, 1], state: "minecraft:netherrack"},
        {pos: [4, 2, 2], state: "minecraft:netherrack"},
        {pos: [4, 2, 3], state: "minecraft:netherrack"},
        {pos: [4, 2, 4], state: "minecraft:netherrack"},
        {pos: [4, 2, 5], state: "minecraft:netherrack"},
        {pos: [2, 3, 1], state: "minecraft:obsidian"},
        {pos: [2, 3, 2], state: "minecraft:nether_portal{axis:z}"},
        {pos: [2, 3, 3], state: "minecraft:nether_portal{axis:z}"},
        {pos: [2, 3, 4], state: "minecraft:obsidian"},
        {pos: [2, 4, 1], state: "minecraft:obsidian"},
        {pos: [2, 4, 2], state: "minecraft:nether_portal{axis:z}"},
        {pos: [2, 4, 3], state: "minecraft:nether_portal{axis:z}"},
        {pos: [2, 4, 4], state: "minecraft:obsidian"},
        {pos: [2, 5, 1], state: "minecraft:obsidian"},
        {pos: [2, 5, 2], state: "minecraft:nether_portal{axis:z}"},
        {pos: [2, 5, 3], state: "minecraft:nether_portal{axis:z}"},
        {pos: [2, 5, 4], state: "minecraft:obsidian"},
        {pos: [2, 6, 1], state: "minecraft:obsidian"},
        {pos: [2, 6, 2], state: "minecraft:obsidian"},
        {pos: [2, 6, 3], state: "minecraft:obsidian"},
        {pos: [2, 6, 4], state: "minecraft:obsidian"}
    ],
    entities: [],
    palette: [
        "minecraft:netherrack",
        "minecraft:bedrock",
        "minecraft:obsidian",
        "minecraft:nether_portal{axis:z}"
    ]
}