{
    DataVersion: 3465,
    size: [5, 10, 5],
    data: [
        {pos: [1, 0, 1], state: "minecraft:dirt"},
        {pos: [1, 0, 2], state: "minecraft:dirt"},
        {pos: [1, 0, 3], state: "minecraft:dirt"},
        {pos: [2, 0, 1], state: "minecraft:dirt"},
        {pos: [2, 0, 2], state: "minecraft:bedrock"},
        {pos: [2, 0, 3], state: "minecraft:dirt"},
        {pos: [3, 0, 1], state: "minecraft:dirt"},
        {pos: [3, 0, 2], state: "minecraft:dirt"},
        {pos: [3, 0, 3], state: "minecraft:dirt"},
        {pos: [1, 1, 1], state: "minecraft:dirt"},
        {pos: [1, 1, 2], state: "minecraft:dirt"},
        {pos: [1, 1, 3], state: "minecraft:dirt"},
        {pos: [2, 1, 1], state: "minecraft:dirt"},
        {pos: [2, 1, 2], state: "minecraft:dirt"},
        {pos: [2, 1, 3], state: "minecraft:dirt"},
        {pos: [3, 1, 1], state: "minecraft:dirt"},
        {pos: [3, 1, 2], state: "minecraft:dirt"},
        {pos: [3, 1, 3], state: "minecraft:dirt"},
        {pos: [1, 2, 1], state: "minecraft:grass_block{snowy:false}"},
        {pos: [1, 2, 2], state: "minecraft:grass_block{snowy:false}"},
        {pos: [1, 2, 3], state: "minecraft:grass_block{snowy:false}"},
        {pos: [2, 2, 1], state: "minecraft:grass_block{snowy:false}"},
        {pos: [2, 2, 2], state: "minecraft:dirt"},
        {pos: [2, 2, 3], state: "minecraft:grass_block{snowy:false}"},
        {pos: [3, 2, 1], state: "minecraft:grass_block{snowy:false}"},
        {pos: [3, 2, 2], state: "minecraft:grass_block{snowy:false}"},
        {pos: [3, 2, 3], state: "minecraft:grass_block{snowy:false}"},
        {pos: [2, 3, 2], state: "minecraft:oak_log{axis:y}"},
        {pos: [2, 4, 2], state: "minecraft:oak_log{axis:y}"},
        {pos: [0, 5, 0], state: "minecraft:oak_leaves{distance:4,persistent:false,waterlogged:false}"},
        {pos: [0, 5, 1], state: "minecraft:oak_leaves{distance:3,persistent:false,waterlogged:false}"},
        {pos: [0, 5, 2], state: "minecraft:oak_leaves{distance:2,persistent:false,waterlogged:false}"},
        {pos: [0, 5, 3], state: "minecraft:oak_leaves{distance:3,persistent:false,waterlogged:false}"},
        {pos: [1, 5, 0], state: "minecraft:oak_leaves{distance:3,persistent:false,waterlogged:false}"},
        {pos: [1, 5, 1], state: "minecraft:oak_leaves{distance:2,persistent:false,waterlogged:false}"},
        {pos: [1, 5, 2], state: "minecraft:oak_leaves{distance:1,persistent:false,waterlogged:false}"},
        {pos: [1, 5, 3], state: "minecraft:oak_leaves{distance:2,persistent:false,waterlogged:false}"},
        {pos: [1, 5, 4], state: "minecraft:oak_leaves{distance:3,persistent:false,waterlogged:false}"},
        {pos: [2, 5, 0], state: "minecraft:oak_leaves{distance:2,persistent:false,waterlogged:false}"},
        {pos: [2, 5, 1], state: "minecraft:oak_leaves{distance:1,persistent:false,waterlogged:false}"},
        {pos: [2, 5, 2], state: "minecraft:oak_log{axis:y}"},
        {pos: [2, 5, 3], state: "minecraft:oak_leaves{distance:1,persistent:false,waterlogged:false}"},
        {pos: [2, 5, 4], state: "minecraft:oak_leaves{distance:2,persistent:false,waterlogged:false}"},
        {pos: [3, 5, 0], state: "minecraft:oak_leaves{distance:3,persistent:false,waterlogged:false}"},
        {pos: [3, 5, 1], state: "minecraft:oak_leaves{distance:2,persistent:false,waterlogged:false}"},
        {pos: [3, 5, 2], state: "minecraft:oak_leaves{distance:1,persistent:false,waterlogged:false}"},
        {pos: [3, 5, 3], state: "minecraft:oak_leaves{distance:2,persistent:false,waterlogged:false}"},
        {pos: [3, 5, 4], state: "minecraft:oak_leaves{distance:3,persistent:false,waterlogged:false}"},
        {pos: [4, 5, 0], state: "minecraft:oak_leaves{distance:4,persistent:false,waterlogged:false}"},
        {pos: [4, 5, 1], state: "minecraft:oak_leaves{distance:3,persistent:false,waterlogged:false}"},
        {pos: [4, 5, 2], state: "minecraft:oak_leaves{distance:2,persistent:false,waterlogged:false}"},
        {pos: [4, 5, 3], state: "minecraft:oak_leaves{distance:3,persistent:false,waterlogged:false}"},
        {pos: [4, 5, 4], state: "minecraft:oak_leaves{distance:4,persistent:false,waterlogged:false}"},
        {pos: [0, 6, 0], state: "minecraft:oak_leaves{distance:4,persistent:false,waterlogged:false}"},
        {pos: [0, 6, 1], state: "minecraft:oak_leaves{distance:3,persistent:false,waterlogged:false}"},
        {pos: [0, 6, 2], state: "minecraft:oak_leaves{distance:2,persistent:false,waterlogged:false}"},
        {pos: [0, 6, 3], state: "minecraft:oak_leaves{distance:3,persistent:false,waterlogged:false}"},
        {pos: [1, 6, 0], state: "minecraft:oak_leaves{distance:3,persistent:false,waterlogged:false}"},
        {pos: [1, 6, 1], state: "minecraft:oak_leaves{distance:2,persistent:false,waterlogged:false}"},
        {pos: [1, 6, 2], state: "minecraft:oak_leaves{distance:1,persistent:false,waterlogged:false}"},
        {pos: [1, 6, 3], state: "minecraft:oak_leaves{distance:2,persistent:false,waterlogged:false}"},
        {pos: [1, 6, 4], state: "minecraft:oak_leaves{distance:3,persistent:false,waterlogged:false}"},
        {pos: [2, 6, 0], state: "minecraft:oak_leaves{distance:2,persistent:false,waterlogged:false}"},
        {pos: [2, 6, 1], state: "minecraft:oak_leaves{distance:1,persistent:false,waterlogged:false}"},
        {pos: [2, 6, 2], state: "minecraft:oak_log{axis:y}"},
        {pos: [2, 6, 3], state: "minecraft:oak_leaves{distance:1,persistent:false,waterlogged:false}"},
        {pos: [2, 6, 4], state: "minecraft:oak_leaves{distance:2,persistent:false,waterlogged:false}"},
        {pos: [3, 6, 0], state: "minecraft:oak_leaves{distance:3,persistent:false,waterlogged:false}"},
        {pos: [3, 6, 1], state: "minecraft:oak_leaves{distance:2,persistent:false,waterlogged:false}"},
        {pos: [3, 6, 2], state: "minecraft:oak_leaves{distance:1,persistent:false,waterlogged:false}"},
        {pos: [3, 6, 3], state: "minecraft:oak_leaves{distance:2,persistent:false,waterlogged:false}"},
        {pos: [3, 6, 4], state: "minecraft:oak_leaves{distance:3,persistent:false,waterlogged:false}"},
        {pos: [4, 6, 1], state: "minecraft:oak_leaves{distance:3,persistent:false,waterlogged:false}"},
        {pos: [4, 6, 2], state: "minecraft:oak_leaves{distance:2,persistent:false,waterlogged:false}"},
        {pos: [4, 6, 3], state: "minecraft:oak_leaves{distance:3,persistent:false,waterlogged:false}"},
        {pos: [4, 6, 4], state: "minecraft:oak_leaves{distance:4,persistent:false,waterlogged:false}"},
        {pos: [1, 7, 1], state: "minecraft:oak_leaves{distance:2,persistent:false,waterlogged:false}"},
        {pos: [1, 7, 2], state: "minecraft:oak_leaves{distance:1,persistent:false,waterlogged:false}"},
        {pos: [2, 7, 1], state: "minecraft:oak_leaves{distance:1,persistent:false,waterlogged:false}"},
        {pos: [2, 7, 2], state: "minecraft:oak_log{axis:y}"},
        {pos: [2, 7, 3], state: "minecraft:oak_leaves{distance:1,persistent:false,waterlogged:false}"},
        {pos: [3, 7, 2], state: "minecraft:oak_leaves{distance:1,persistent:false,waterlogged:false}"},
        {pos: [3, 7, 3], state: "minecraft:oak_leaves{distance:2,persistent:false,waterlogged:false}"},
        {pos: [1, 8, 2], state: "minecraft:oak_leaves{distance:2,persistent:false,waterlogged:false}"},
        {pos: [2, 8, 1], state: "minecraft:oak_leaves{distance:2,persistent:false,waterlogged:false}"},
        {pos: [2, 8, 2], state: "minecraft:oak_leaves{distance:1,persistent:false,waterlogged:false}"},
        {pos: [2, 8, 3], state: "minecraft:oak_leaves{distance:2,persistent:false,waterlogged:false}"},
        {pos: [3, 8, 2], state: "minecraft:oak_leaves{distance:2,persistent:false,waterlogged:false}"}
    ],
    entities: [],
    palette: [
        "minecraft:dirt",
        "minecraft:bedrock",
        "minecraft:grass_block{snowy:false}",
        "minecraft:oak_log{axis:y}",
        "minecraft:oak_leaves{distance:4,persistent:false,waterlogged:false}",
        "minecraft:oak_leaves{distance:3,persistent:false,waterlogged:false}",
        "minecraft:oak_leaves{distance:2,persistent:false,waterlogged:false}",
        "minecraft:oak_leaves{distance:1,persistent:false,waterlogged:false}"
    ]
}